---
title: (Nodejs) 2.1 promise, async await
date: "2020-09-22"
description: 
---

# 1. 기존의 비동기 작업

콜백지옥
```js
  const printAll = () => {
    printString('a', () => {
      printString('b', () => {
        printString('c', () => {})
      })
    })
  }
```

- 위와 같은 상황에서 좀 더 코드를 간결하게 만들기 위한 노력.


# 2 해결책1: Promise
Promise: [MDN Link](https://developer.mozilla.org/en-US/docs/Web/JavaScript/Reference/Global_Objects/Promise)
- 비동기 작업이 맞이할 미래의 완료 또는 실패와 그 결과값을 나타낸다. 즉, 이 말대로라면 Promise는 세가지 상태를 가진다고 볼 수 있다.
    - 현재: pending인 상태.
    - 미래에 완료: resolve가 되어 then이 실행된 상태
    - 미래에 실패: reject가 되어 catch가 실행된 상태

## 2.1 Pending
처음 선언할 때는, pending인 상태이다. 비동기 함수이기 때문에 console.log해봐야 pending상태라고만 뜨고 출력값이 보이지 않는다. 이는 비동기 함수의 경우 스크립트를 모두 읽은 다음에야 실행되기 때문에 생기는 일이다.

```js
const condition = true;
const promise = new Promise((resolve, reject) => {
    if(condition){
      resolve(argOfthen);
    }else{
      reject(argOfcatch);
    } 
  })
```

## 2.2 Resolve & Reject

```js
promise
	.then( argOfthen => {	
        실행할 코드
        return value
    })
  .then(value => {
        실행할 코드
    }
	.catch( argOfcatch => {	
		실행할 코드
	})
	.finally(() => {
		무조건 실행
	})
```

## 2.3 Promise Chaining
return value인 경우 vs return new Promise인 경우
- 다음에 then이 있다면, return value의 경우, 반드시 다음 then의 인자로 들어가게 된다. (인자를 받는다면!) 
- 하지만, return new Promise의 경우, Promise가 resolve가 되어야만 then으로 이동한다. 만일 reject가 된다면, 다음에 then이 몇개가 오든간에 싹 무시하고 catch로 이동해 에러를 뱉는다.

```js
promise
  .then( arg1 => {
    return new Promise((resolve, reject) => {
      resolve(arg2);
    });
  })
  .then( arg2 => {
    return new Promise((resolve, reject) => {
      resolve(arg3);
    });
  })
  .then((arg3) => {
  })
  .catch((error) => {
    console.error(error);
  });
```


## 2.4 Promise.all
then으로 가려면
- 모든 promise가 resolve상태여야 함. 하나라도 reject라면, catch로 빠짐.

리턴값
- 배열 형식으로 리턴함. 

```js
const promise1 = new Promise(...)
const promise2 = new Promise(...)
Promise.all([promise1, promise2])  // function 내라면, Promise.all 자체에도 return해줘야.
  .then((result) => {
    return result       // 
  })
  .catch((error) => {
    console.error(error);
  });
```

# 3 해결책2: async / await
- then 대신, await키워드를 이용해 user변수에 대한 처리를 할 수 있음.

## 3.1 Pending


## 3.2 Resolve 받는 부분은 await
```js
const promise1 = new Promise(...)
const promise2 = new Promise(...)
async function () { 
  try{
    result = await promise1
    result = await promise2
  }  
  } catch (error) {
    console.error(error);
  }
}
```

## 3.2 promise.all => for await of
```js
const promise1 = Promise.resolve('성공1');
const promise2 = Promise.resolve('성공2');
(async () => {
  for await (promise of [promise1, promise2]) {
    console.log(promise);
  }
})();
```


